Workbook

Sheet Main
M2: founded | N2: 2004
M3: IPO | N3: 2012
D5: #VALUE! | M5: HQ Menlo Park, CA
D7: Q423 | E7: Q424 | F7: Q125 | G7: Q225 | H7: Q225 | I7: Q425 | J7: Q126
C8: Price | D8: 325 | E8: 549 | F8: 695.21 | G8: 775 | H8: 661 | I8: 670 | J8: 577 | M8: CFO | N8: Susan Li
C9: Shares | D9: 2524.449 | E9: 2524.449 | F9: 2527 | G9: 2518 | H9: =2177.889269+342.638328 -> 2520.5276 | I9: 2525 | J9: =2196.045588+342.377716 -> 2538.4233 | M9: CEO | N9: The Zuck
C10: MC | D10: =D9*D8 -> 820445.93 | E10: 1385922.5 | F10: =+F9*F8 -> 1756795.7 | G10: =+G9*G8 -> 1951450 | H10: =+H9*H8 -> 1666068.7 | I10: =+I9*I8 -> 1691750 | J10: =+J9*J8 -> 1464670.2 | M10: COO | N10: Javier Olivan
C11: Cash | D11: =41862+23541+16169 -> 81572 | E11: 77815 | F11: =28750+41480+6168 -> 76398 | G11: =12005+35066+21988 -> 69059 | H11: =10187+34261+25074 -> 69522 | I11: =35873+45719 -> 81592 | J11: =+Model!AL102 -> 81180
C12: Debt | D12: =4849+863+18385+1623 -> 25720 | E12: 28826 | F12: 28829 | G12: 28832 | H12: 28834 | I12: 58744 | J12: =+Model!AL103 -> 58748 | M12: BOD | N12: Andreesen, Alford, Houston, Kiellefer, Kimmitt, Sandberg, Travis, Xu
C13: EV | D13: =D10-D11+D12 -> 764593.93 | E13: 1336933.5 | F13: =+F10+F12-F11 -> 1709226.7 | G13: =+G10+G12-G11 -> 1911223 | H13: =+H10+H12-H11 -> 1625380.7 | I13: =+I10+I12-I11 -> 1668902 | J13: =+J10+J12-J11 -> 1442238.2 | M13: IR | N13: Deborah Crawford | P13: investor@fb.com
C15: PP&E | F15: 133567 | G15: 147039 | H15: 160270 | I15: 176400 | J15: 194776
M17: Chief AI | N17: Alexandr Wang
F18: cause shkreli took out some one time loss of 16B relaity labs
C19: net inc | F19: 83000 | G19: 71507 | H19: 74882 | I19: 76387 | J19: 78451
C20: RL loss | G20: =-4530*4 -> -18120 | H20: =-4390*4 -> -17560 | I20: -19193 | J20: -19011
C21: inc no RL | G21: =+G19-G20 -> 89627 | H21: =+H19-H20 -> 92442 | I21: =+I19-I20 -> 95580 | J21: =+J19-J20 -> 97462
C22: EV/NI | G22: =+G13/G21 -> 21.324188 | H22: =+H13/H21 -> 17.582709 | I22: =+I13/I21 -> 17.460787 | J22: =+J13/J21 -> 14.797955
C29: CFFO | E29: 91378 | F29: 96158 | G29: 101889 | H29: 107624 | I29: 115800 | J29: 124000
E30: =+E13/E29 -> 14.630803 | F30: =+F13/F29 -> 17.775189 | G30: =+G13/G29 -> 18.757893 | H30: =+H13/H29 -> 15.1024 | I30: =+I13/I29 -> 14.411934 | J30: =+J13/J29 -> 11.630954
C32: FCF | E32: 54122 | F32: 52361 | G32: 49727 | H32: 44891 | I32: 46109 | J32: 48253
E33: =+E13/E32 -> 24.702219 | F33: =+F13/F32 -> 32.643125 | G33: =+G13/G32 -> 38.434311 | H33: =+H13/H32 -> 36.207274 | I33: =+I13/I32 -> 36.194713 | J33: =+J13/J32 -> 29.88909
C36: DAP | E36: =3.35*1000 -> 3350 | H36: 3540 | I36: 3580
C37: PPU | E37: =+E10/E36 -> 413.70821 | H37: =+H10/H36 -> 470.64089 | I37: =+I10/I36 -> 472.55587
C38: ARPP | E38: 49.63 | H38: 54.72 | I38: 54.72
C43: NTM CFFO | H43: 128983 | I43: 131340
H44: =+H13/H43 -> 12.601511 | I44: =+I13/I43 -> 12.706731

Sheet Model
A1: Main
B2: M usd | E2: Q417 | F2: Q118 | G2: Q218 | H2: Q318 | I2: Q418 | J2: Q119 | K2: Q219 | L2: Q319 | M2: Q419 | N2: Q120 | O2: Q220 | P2: Q320 | Q2: Q420 | R2: Q121 | S2: Q221 | T2: Q321 | U2: Q421 | V2: Q122 | W2: Q222 | X2: Q322 | Y2: Q422 | Z2: Q123 | AA2: Q223 | AB2: Q323 | AC2: Q423 | AD2: Q124 | AE2: Q224 | AF2: Q324 | AG2: Q424 | AH2: Q125 | AI2: Q225 | AJ2: Q325 | AK2: Q425 | AL2: Q126 | AM2: Q226 | AN2: Q326 | AO2: Q426 | AP2: Q127 | AQ2: Q227 | AU2: 2010 | AV2: 2011 | AW2: 2012 | AX2: 2013 | AY2: 2014 | AZ2: 2015 | BA2: 2016 | BB2: 2017 | BC2: 2018 | BD2: =BC2+1 -> 2019 | BE2: =BD2+1 -> 2020 | BF2: =BE2+1 -> 2021 | BG2: =BF2+1 -> 2022 | BH2: =BG2+1 -> 2023 | BI2: =BH2+1 -> 2024 | BJ2: =BI2+1 -> 2025 | BK2: =BJ2+1 -> 2026 | ... FP2: =FO2+1 -> 2135
B5: world population | AI5: 8239 | AJ5: 8255.488 | AL5: 8290.179 | BA5: 7558.554 | BB5: 7645.617 | BC5: 7729.902 | BD5: 7811.293 | BE5: 7887 | BF5: 7954.448 | BG5: 8021.407 | BH5: 8091.734 | BI5: 8161.972 | BJ5: 8233.8887 | BK5: =+BJ5*(BJ5/BI5) -> 8306.4391 | BL5: =+BK5*(BK5/BJ5) -> 8379.6288 | BM5: =+BL5*(BL5/BK5) -> 8453.4633 | BN5: =+BM5*(BM5/BL5) -> 8527.9484 | BO5: =+BN5*(BN5/BM5) -> 8603.0898 | BP5: =+BO5*(BO5/BN5) -> 8678.8933 | BQ5: =+BP5*(BP5/BO5) -> 8755.3647 | BR5: =+BQ5*(BQ5/BP5) -> 8832.5099 | ... BT5: =+BS5*(BS5/BR5) -> 8988.8456
B6: cannot have FB (China, Iran, North Korea, Birma, Russia, Turkmenistan, Uganda) | AI6: =143.8+1411+54.13+90.61+26.42+7.364+48.66 -> 1781.984 | AJ6: =+AI6+4.75*3 -> 1796.234 | AL6: =1410+93.17+140+40 -> 1683.17 | BI6: =143.8+1411+54.13+90.61+26.42+7.364+48.66 -> 1781.984 | BJ6: 1801 | BK6: 1804 | BL6: 1806 | BM6: 1808 | BN6: 1809 | BO6: 1810 | BP6: 1810 | BQ6: 1809 | BR6: 1808 | BS6: 1806 | BT6: 1804 | BU6: grok estimates
B7: can have FB | AI7: =+AI5-AI6 -> 6457.016 | AJ7: =+AJ5-AJ6 -> 6459.254 | AL7: =+AL5-AL6 -> 6607.009 | BI7: =+BI5-BI6 -> 6379.988 | BJ7: =+BJ5-BJ6 -> 6432.8887 | BK7: =+BK5-BK6 -> 6502.4391 | BL7: =+BL5-BL6 -> 6573.6288 | BM7: =+BM5-BM6 -> 6645.4633 | BN7: =+BN5-BN6 -> 6718.9484 | BO7: =+BO5-BO6 -> 6793.0898 | BP7: =+BP5-BP6 -> 6868.8933 | ... BT7: =+BT5-BT6 -> 7184.8456
B9: has FB from those who can | AI9: =+AI13/AI7*1000 -> 0.53894864 | AJ9: =+AJ13/AJ7*1000 -> 0.5480509 | AL9: =+AL13/AL7*1000 -> 0.53882173 | BI9: =+BI13/BI7*1000 -> 0.52507936 | BJ9: =+BJ13/BJ7*1000 -> 0.5502971 | BK9: =+BK13/BK7*1000 -> 0.57544253 | BL9: =+BL13/BL7*1000 -> 0.60165574 | BM9: =+BM13/BM7*1000 -> 0.62907577 | BN9: =+BN13/BN7*1000 -> 0.65766072 | BO9: =+BO13/BO7*1000 -> 0.68756038 | BP9: =+BP13/BP7*1000 -> 0.71873106 | ... BT9: =+BT13/BT7*1000 -> 0.85770056
B12: DAUs | M12: 1.657 | N12: 1.734 | O12: 1.785 | P12: 1.82 | Q12: 1.845 | R12: 1.878 | S12: 1.908 | AW12: 0.618 | AX12: 0.757 | AY12: 0.89 | AZ12: 1.038 | BA12: 1.227 | BB12: 1.401
B13: DAP (family daily active people) using one of the apps at least once a day | N13: 2.03 | O13: 2.701 | P13: 2.74 | Q13: 2.797 | R13: 2.853 | S13: 2.895 | T13: 2.91 | U13: 2.91 | V13: 2.87 | W13: 2.88 | X13: 2.93 | Y13: 2.96 | Z13: 3.02 | AA13: 3.07 | AB13: 3.14 | AC13: 3.19 | AD13: 3.24 | AE13: 3.27 | AF13: 3.29 | AG13: 3.35 | AH13: 3.43 | AI13: 3.48 | AJ13: 3.54 | AK13: 3.58 | AL13: 3.56 | BC13: 2.03 | BD13: 2.26 | BE13: 2.6 | BF13: 2.82 | BG13: 2.96 | BH13: 3.19 | BI13: 3.35 | BJ13: 3.54 | BK13: =+BJ13*(1+BK42) -> 3.74178 | BL13: =+BK13*(1+BL42) -> 3.9550615 | BM13: =+BL13*(1+BM42) -> 4.1805 | BN13: =+BM13*(1+BN42) -> 4.4187885 | BO13: =+BN13*(1+BO42) -> 4.6706594 | BP13: =+BO13*(1+BP42) -> 4.936887 | BQ13: =+BP13*(1+BQ42) -> 5.2182895 | BR13: =+BQ13*(1+BR42) -> 5.5157321 | ... BT13: =+BS13*(1+BT42) -> 6.1624461
B14: ARPP | N14: =+N26/(N13*1000) -> 8.7374384 | O14: =+O26/(O13*1000) -> 6.9185487 | R14: =+R26/(R13*1000) -> 9.1731511 | S14: =+S26/(S13*1000) -> 10.043869 | V14: =+V26/(V13*1000) -> 9.7240418 | W14: =+W26/(W13*1000) -> 10.007639 | X14: 9.44 | Y14: 10.68 | Z14: 9.47 | AA14: 10.42 | AB14: 10.93 | AC14: 12.33 | AD14: 11.2 | AE14: 11.89 | AF14: 12.29 | AG14: 14.25 | AH14: =+AH26/(AH13*1000) -> 12.336443 | AI14: =+AI26/(AI13*1000) -> 13.654023 | AJ14: =+AJ26/(AJ13*1000) -> 14.475141 | AK14: =+AK26/(AK13*1000) -> 16.729888 | AL14: =+AL26/(AL13*1000) -> 15.817697 | BC14: =+BD14/1.15 -> 21.456419 | BD14: =+BE14/1.15 -> 24.674881 | BE14: =+BF14/1.15 -> 28.376114 | BF14: =+BG14/1.15 -> 32.632531 | BG14: =+BH14/1.15 -> 37.52741 | BH14: =+BI14/1.15 -> 43.156522 | BI14: 49.63 | BJ14: 54.72 | BK14: =+BJ14*(1+BK43) -> 60.35616 | BL14: =+BK14*(1+BL43) -> 66.572844 | BM14: =+BL14*(1+BM43) -> 73.429847 | BN14: =+BM14*(1+BN43) -> 80.993122 | BO14: =+BN14*(1+BO43) -> 89.335413 | BP14: =+BO14*(1+BP43) -> 98.536961 | BQ14: =+BP14*(1+BQ43) -> 108.68627 | BR14: =+BQ14*(1+BR43) -> 119.88095 | ... BT14: =+BS14*(1+BT43) -> 145.84825
B16: new users | R16: =+(R13-N13)*1000 -> 823 | S16: =+(S13-O13)*1000 -> 194 | T16: =+(T13-P13)*1000 -> 170 | U16: =+(U13-Q13)*1000 -> 113 | V16: =+(V13-R13)*1000 -> 17 | W16: =+(W13-S13)*1000 -> -15 | X16: =+(X13-T13)*1000 -> 20 | Y16: =+(Y13-U13)*1000 -> 50 | ... AL16: =+(AL13-AH13)*1000 -> 130 | BD16: =+(BD13-BC13)*1000 -> 230 | BE16: =+(BE13-BD13)*1000 -> 340 | BF16: =+(BF13-BE13)*1000 -> 220 | BG16: =+(BG13-BF13)*1000 -> 140 | BH16: =+(BH13-BG13)*1000 -> 230 | BI16: =+(BI13-BH13)*1000 -> 160 | BJ16: =+(BJ13-BI13)*1000 -> 190
B17: UAC | AA17: =+AA30/AA16 -> 16.6 | AB17: =+AB30/AB16 -> 13.7 | AC17: =+AC30/AC16 -> 14.026087 | AD17: =+AD30/AD16 -> 11.654545 | AE17: =+AE30/AE16 -> 13.605 | AF17: =+AF30/AF16 -> 18.813333 | AG17: =+AG30/AG16 -> 20.25 | AH17: =+AH30/AH16 -> 14.510526 | ... AL17: =+AL30/AL16 -> 22.369231 | BD17: =+BD30/BD16 -> 42.93913 | BE17: =+BE30/BE16 -> 34.091176 | BF17: =+BF30/BF16 -> 63.831818 | BG17: =+BG30/BG16 -> 109.01429 | BH17: =+BH30/BH16 -> 53.482609 | BI17: =+BI30/BI16 -> 70.91875 | BJ17: =+BJ30/BJ16 -> 63.110526
B20: Reality Labs loss | Y20: -4279 | AC20: -4646 | AD20: =-8334-AE20 -> -3846 | AE20: -4488 | AF20: =+BI20-AE20-AD20-AG20 -> -4749 | AG20: -4646 | AH20: =-8739-AI20 -> -4209 | AI20: -4530 | AJ20: -4432 | AK20: -6021 | AL20: -4028 | BG20: -13717 | BH20: -16120 | BI20: -17729 | BJ20: =-4370*4 -> -17480 | BK20: =-4370*4 -> -17480 | BL20: =-4370*4 -> -17480 | BM20: =-4370*4 -> -17480 | BN20: =-4370*4 -> -17480 | BO20: =-4370*4 -> -17480 | BP20: =-4370*4 -> -17480 | BQ20: =-4370*4 -> -17480 | ... BT20: =-4370*4 -> -17480
B23: advertising | M23: 20736 | N23: 17737 | O23: 18321 | P23: 21221 | Q23: 27187 | R23: 25439 | S23: 28580 | T23: 28276 | U23: 32639 | Y23: 31254 | AC23: 38706 | AD23: 35635 | AE23: 38329 | AF23: =+BI23-AE23-AD23-AG23 -> 39886 | AG23: 46783 | AH23: 41392 | AI23: 46563 | AJ23: 50082 | AK23: 58137 | AL23: 55024 | BE23: =+SUM(N23:Q23) -> 84466 | BF23: =+SUM(R23:U23) -> 114934 | BG23: 113642 | BH23: 131948 | BI23: 160633 | BJ23: 196175 | BK23: =+BK13*BK14*1000 -> 225839.47 | BL23: =+BL13*BL14*1000 -> 263299.69 | BM23: =+BM13*BM14*1000 -> 306973.47 | BN23: =+BN13*BN14*1000 -> 357891.47 | BO23: =+BO13*BO14*1000 -> 417255.29 | BP23: =+BP13*BP14*1000 -> 486465.84
B24: other revenue | M24: 346 | N24: 297 | O24: 366 | P24: 249 | Q24: 885 | R24: 732 | S24: 497 | T24: 734 | U24: 1032 | Y24: 184 | AC24: 334 | AD24: 380 | AE24: 389 | AF24: =+BI24-AE24-AD24-AG24 -> 434 | AG24: 519 | AH24: 510 | AI24: 583 | AJ24: 690 | AK24: 801 | AL24: 885 | BE24: =+SUM(N24:Q24) -> 1797 | BF24: =+SUM(R24:U24) -> 2995 | BG24: 808 | BH24: 1058 | BI24: 1722 | BJ24: 2584 | BK24: =+BJ24*1.03 -> 2661.52 | BL24: =+BK24*1.03 -> 2741.3656 | BM24: =+BL24*1.03 -> 2823.6066 | BN24: =+BM24*1.03 -> 2908.3148 | BO24: =+BN24*1.03 -> 2995.5642 | BP24: =+BO24*1.03 -> 3085.4311
B25: reality labs | M25: 0 | N25: 0 | O25: 0 | P25: 0 | Q25: 0 | R25: 0 | S25: 0 | T25: 0 | U25: 0 | Y25: 727 | AC25: 1071 | AD25: 440 | AE25: 353 | AF25: =+BI25-AE25-AD25-AG25 -> 270 | AG25: 1083 | AH25: 412 | AI25: 370 | AJ25: 470 | AK25: 955 | AL25: 402 | BE25: =+SUM(N25:Q25) -> 0 | BF25: =+SUM(R25:U25) -> 0 | BG25: 2159 | BH25: 1896 | BI25: 2146 | BJ25: 2207 | BK25: =+BJ25*1.03 -> 2273.21 | BL25: =+BK25*1.03 -> 2341.4063 | BM25: =+BL25*1.03 -> 2411.6485 | BN25: =+BM25*1.03 -> 2483.9979 | BO25: =+BN25*1.03 -> 2558.5179 | BP25: =+BO25*1.03 -> 2635.2734
B26: Revenue | M26: =+SUM(M23:M25) -> 21082 | N26: 17737 | O26: 18687 | P26: =+SUM(P23:P25) -> 21470 | Q26: =+SUM(Q23:Q25) -> 28072 | R26: 26171 | S26: 29077 | T26: =+SUM(T23:T25) -> 29010 | U26: =+SUM(U23:U25) -> 33671 | V26: 27908 | W26: 28822 | Y26: =+SUM(Y23:Y25) -> 32165 | Z26: 28645 | AA26: 31999 | AB26: 34146 | AC26: =+SUM(BH26)-SUM(Z26:AB26) -> 40112 | AD26: 36455 | AE26: 39071 | AF26: 40589 | AG26: =+SUM(BI26)-SUM(AD26:AF26) -> 48386 | AH26: 42314 | AI26: 47516 | AJ26: =+SUM(AJ23:AJ25) -> 51242 | AK26: 59893 | AL26: 56311 | AM26: 59520 | AN26: 62760 | AO26: 72840 | AX26: 7872 | AY26: 12466 | AZ26: 17928 | BA26: 27638 | BB26: 40653 | BC26: 55838 | BD26: 70697 | BE26: 85965 | BF26: 117929 | BG26: 116609 | BH26: 134902 | BI26: 164501 | BJ26: 200966 | BK26: =+SUM(BK23:BK25) -> 230774.2 | BL26: =+SUM(BL23:BL25) -> 268382.46 | BM26: =+SUM(BM23:BM25) -> 312208.73 | BN26: =+SUM(BN23:BN25) -> 363283.78 | BO26: =+SUM(BO23:BO25) -> 422809.37 | BP26: =+BP14*BP13*1000 -> 486465.84 | BQ26: =+BQ14*BQ13*1000 -> 567156.42 | BR26: =+BR14*BR13*1000 -> 661231.22 | BS26: =+BS14*BS13*1000 -> 770910.3 | BT26: =+BT14*BT13*1000 -> 898781.96
B27: Cost of revenue | N27: 3459 | O27: 3829 | R27: 5131 | S27: 5399 | V27: 6005 | W27: 5192 | Z27: 6108 | AA27: 5945 | AB27: 6210 | AC27: =+SUM(BH27)-SUM(Z27:AB27) -> 7696 | AD27: 6640 | AE27: 7308 | AF27: 7375 | AG27: =+SUM(BI27)-SUM(AD27:AF27) -> 8838 | AH27: 7572 | AI27: 8491 | AJ27: 9206 | AK27: 10905 | AL27: 10218 | AX27: 1875 | AY27: 2153 | AZ27: 2867 | BA27: 3789 | BB27: 5454 | BC27: 9355 | BD27: 12770 | BE27: 16692 | BF27: 22649 | BG27: 25249 | BH27: 25959 | BI27: 30161 | BJ27: 36175 | BK27: =10900*4 -> 43600 | BL27: =+BK27*1.03 -> 44908 | BM27: =+BL27*1.03 -> 46255.24 | BN27: =+BM27*1.03 -> 47642.897 | BO27: =+BN27*1.03 -> 49072.184 | BP27: =+BO27*1.03 -> 50544.35
B28: Gross profit | N28: =N26-N27 -> 14278 | O28: =O26-O27 -> 14858 | R28: =R26-R27 -> 21040 | S28: =S26-S27 -> 23678 | V28: =V26-V27 -> 21903 | W28: =W26-W27 -> 23630 | Z28: =Z26-Z27 -> 22537 | AA28: =AA26-AA27 -> 26054 | AB28: =AB26-AB27 -> 27936 | AC28: =+SUM(BH28)-SUM(Z28:AB28) -> 32416 | AD28: =AD26-AD27 -> 29815 | AE28: =AE26-AE27 -> 31763 | AF28: =AF26-AF27 -> 33214 | AG28: =+SUM(BI28)-SUM(AD28:AF28) -> 39548 | AH28: =AH26-AH27 -> 34742 | AI28: =AI26-AI27 -> 39025 | AJ28: =AJ26-AJ27 -> 42036 | AK28: =AK26-AK27 -> 48988 | AL28: =AL26-AL27 -> 46093 | AX28: =AX26-AX27 -> 5997 | AY28: =AY26-AY27 -> 10313 | AZ28: =AZ26-AZ27 -> 15061 | BA28: =BA26-BA27 -> 23849 | BB28: =BB26-BB27 -> 35199 | BC28: =BC26-BC27 -> 46483 | BD28: =BD26-BD27 -> 57927 | BE28: =BE26-BE27 -> 69273 | ... BI28: =BI26-BI27 -> 134340 | BJ28: =+BJ26*BJ46 -> 164791 | BK28: =+BK26*BK46 -> 187174.2 | BL28: =+BL26*BL46 -> 220073.62 | BM28: =+BM26*BM46 -> 256011.16 | BN28: =+BN26*BN46 -> 297892.7 | BO28: =+BO26*BO46 -> 346703.68 | BP28: =+BP26*BP46 -> 398901.99
B29: R&D | N29: 4015 | O29: 4462 | R29: 5197 | S29: 6096 | V29: 7707 | W29: 8690 | Z29: 9381 | AA29: 9344 | AB29: 9241 | AC29: =+SUM(BH29)-SUM(Z29:AB29) -> 10517 | AD29: 9978 | AE29: 10537 | AF29: 11177 | AG29: =+SUM(BI29)-SUM(AD29:AF29) -> 12181 | AH29: 12150 | AI29: 12942 | AJ29: 15144 | AK29: 17136 | AL29: 17699 | AX29: 1415 | AY29: 2666 | AZ29: 4816 | BA29: 5919 | BB29: 7754 | BC29: 10273 | BD29: 13600 | BE29: 18447 | BF29: 24655 | BG29: 35338 | BH29: 38483 | BI29: 43873 | BJ29: 57372 | BK29: =+AK29*4 -> 68544 | BL29: =+BK29+10000 -> 78544 | BM29: =+BL29+10000 -> 88544 | BN29: =+BM29+10000 -> 98544 | BO29: =+BN29+10000 -> 108544 | BP29: =+BO29+10000 -> 118544
B30: M&S | N30: 2787 | O30: 2840 | R30: 2843 | S30: 3259 | V30: 3312 | W30: 3595 | Z30: 3044 | AA30: 3154 | AB30: 2877 | AC30: =+SUM(BH30)-SUM(Z30:AB30) -> 3226 | AD30: 2564 | AE30: 2721 | AF30: 2822 | AG30: =+SUM(BI30)-SUM(AD30:AF30) -> 3240 | AH30: 2757 | AI30: 2979 | AJ30: 2845 | AK30: 3410 | AL30: 2908 | AX30: 997 | AY30: 1680 | AZ30: 2725 | BA30: 3772 | BB30: 4725 | BC30: 7846 | BD30: 9876 | BE30: 11591 | BF30: 14043 | BG30: 15262 | BH30: 12301 | BI30: 11347 | BJ30: 11991 | BK30: =+BJ30*1.03 -> 12350.73 | BL30: =+BK30*1.03 -> 12721.252 | BM30: =+BL30*1.03 -> 13102.889 | BN30: =+BM30*1.03 -> 13495.976 | BO30: =+BN30*1.03 -> 13900.855 | BP30: =+BO30*1.03 -> 14317.881
B31: G&A | N31: 1583 | O31: 1593 | R31: 1622 | S31: 1956 | V31: 2360 | W31: 2987 | Z31: 2885 | AA31: 4164 | AB31: 2070 | AC31: =+SUM(BH31)-SUM(Z31:AB31) -> 2289 | AD31: 3455 | AE31: 3658 | AF31: 1865 | AG31: =+SUM(BI31)-SUM(AD31:AF31) -> 762 | AH31: 2280 | AI31: 2663 | AJ31: 3512 | AK31: 3697 | AL31: 2614 | AX31: 781 | AY31: 973 | AZ31: 1295 | BA31: 1731 | BB31: 2517 | BC31: 3451 | BD31: 10465 | BE31: 6564 | BF31: 9829 | BG31: 11816 | BH31: 11408 | BI31: 9740 | BJ31: 12152 | BK31: =+BJ31*1.03 -> 12516.56 | BL31: =+BK31*1.03 -> 12892.057 | BM31: =+BL31*1.03 -> 13278.819 | BN31: =+BM31*1.03 -> 13677.183 | BO31: =+BN31*1.03 -> 14087.499 | BP31: =+BO31*1.03 -> 14510.124
B32: tot cost | N32: =+SUM(N29:N31) -> 8385 | O32: =+SUM(O29:O31) -> 8895 | R32: =+SUM(R29:R31) -> 9662 | S32: =+SUM(S29:S31) -> 11311 | V32: =+SUM(V29:V31) -> 13379 | W32: =+SUM(W29:W31) -> 15272 | Z32: =+SUM(Z29:Z31) -> 15310 | AA32: =+SUM(AA29:AA31) -> 16662 | AB32: =+SUM(AB29:AB31) -> 14188 | AC32: =+SUM(BH32)-SUM(Z32:AB32) -> 16032 | AD32: =+SUM(AD29:AD31) -> 15997 | AE32: =+SUM(AE29:AE31) -> 16916 | AF32: =+SUM(AF29:AF31) -> 15864 | AG32: =+SUM(BI32)-SUM(AD32:AF32) -> 16183 | AH32: =+SUM(AH29:AH31) -> 17187 | AI32: =+SUM(AI29:AI31) -> 18584 | AJ32: =+SUM(AJ29:AJ31) -> 21501 | AK32: =+SUM(AK29:AK31) -> 24243 | AL32: =+SUM(AL29:AL31) -> 23221 | AX32: =+SUM(AX29:AX31) -> 3193 | AY32: =+SUM(AY29:AY31) -> 5319 | AZ32: =+SUM(AZ29:AZ31) -> 8836 | BA32: =+SUM(BA29:BA31) -> 11422 | BB32: =+SUM(BB29:BB31) -> 14996 | BC32: =+SUM(BC29:BC31) -> 21570 | BD32: =+SUM(BD29:BD31) -> 33941 | BE32: =+SUM(BE29:BE31) -> 36602 | ... BP32: =+SUM(BP29:BP31) -> 147372
B33: operating profit | N33: =N28-N32 -> 5893 | O33: =O28-O32 -> 5963 | R33: =R28-R32 -> 11378 | S33: =S28-S32 -> 12367 | V33: =V28-V32 -> 8524 | W33: =W28-W32 -> 8358 | Z33: =Z28-Z32 -> 7227 | AA33: =AA28-AA32 -> 9392 | AB33: =AB28-AB32 -> 13748 | AC33: =+SUM(BH33)-SUM(Z33:AB33) -> 16384 | AD33: =AD28-AD32 -> 13818 | AE33: =AE28-AE32 -> 14847 | AF33: =AF28-AF32 -> 17350 | AG33: =+SUM(BI33)-SUM(AD33:AF33) -> 23365 | AH33: =AH28-AH32 -> 17555 | AI33: =AI28-AI32 -> 20441 | AJ33: =AJ28-AJ32 -> 20535 | AK33: =AK28-AK32 -> 24745 | AL33: =AL28-AL32 -> 22872 | AX33: =AX28-AX32 -> 2804 | AY33: =AY28-AY32 -> 4994 | AZ33: =AZ28-AZ32 -> 6225 | BA33: =BA28-BA32 -> 12427 | BB33: =BB28-BB32 -> 20203 | BC33: =BC28-BC32 -> 24913 | BD33: =BD28-BD32 -> 23986 | BE33: =BE28-BE32 -> 32671 | ... BP33: =BP28-BP32 -> 251529.98
B34: interest & other | N34: -32 | O34: 168 | R34: 125 | S34: 146 | V34: 384 | W34: -172 | Z34: 80 | AA34: -99 | AB34: 272 | AC34: =+SUM(BH34)-SUM(Z34:AB34) -> 424 | AD34: 365 | AE34: 259 | AF34: 472 | AG34: =+SUM(BI34)-SUM(AD34:AF34) -> 187 | AH34: 827 | AI34: 93 | AJ34: 1128 | AK34: 609 | AL34: -1120 | AX34: -50 | AY34: -84 | AZ34: -31 | BA34: 91 | BB34: 391 | BC34: 448 | BD34: 826 | BE34: 509 | BF34: 531 | BG34: -125 | BH34: 677 | BI34: 1283 | BJ34: 2656 | BK34: =+BJ102*$BY$44 -> 1631.84 | BL34: =+BK102*$BY$44 -> 3291.7087 | BM34: =+BL102*$BY$44 -> 5365.9282 | BN34: =+BM102*$BY$44 -> 7914.1822 | BO34: =+BN102*$BY$44 -> 11047.743 | BP34: =+BO102*$BY$44 -> 14896.955
B35: EBIT | N35: =+SUM(N33:N34) -> 5861 | O35: =+SUM(O33:O34) -> 6131 | R35: =+SUM(R33:R34) -> 11503 | S35: =+SUM(S33:S34) -> 12513 | V35: =+SUM(V33:V34) -> 8908 | W35: =+SUM(W33:W34) -> 8186 | Z35: =+SUM(Z33:Z34) -> 7307 | AA35: =+SUM(AA33:AA34) -> 9293 | AB35: =+SUM(AB33:AB34) -> 14020 | AC35: =+SUM(BH35)-SUM(Z35:AB35) -> 16808 | AD35: =+SUM(AD33:AD34) -> 14183 | AE35: =+SUM(AE33:AE34) -> 15106 | AF35: =+SUM(AF33:AF34) -> 17822 | AG35: =+SUM(BI35)-SUM(AD35:AF35) -> 23552 | AH35: =+SUM(AH33:AH34) -> 18382 | AI35: =+SUM(AI33:AI34) -> 20534 | AJ35: =+SUM(AJ33:AJ34) -> 21663 | AK35: =+SUM(AK33:AK34) -> 25354 | AL35: =+SUM(AL33:AL34) -> 21752 | AX35: =+SUM(AX33:AX34) -> 2754 | AY35: =+SUM(AY33:AY34) -> 4910 | AZ35: =+SUM(AZ33:AZ34) -> 6194 | BA35: =+SUM(BA33:BA34) -> 12518 | BB35: =+SUM(BB33:BB34) -> 20594 | BC35: =+SUM(BC33:BC34) -> 25361 | BD35: =+SUM(BD33:BD34) -> 24812 | BE35: =+SUM(BE33:BE34) -> 33180 | ... BP35: =+SUM(BP33:BP34) -> 266426.94
B36: tax | N36: 959 | O36: 953 | R36: 2006 | S36: 2119 | V36: 1443 | W36: 1499 | Z36: 1598 | AA36: 1505 | AB36: 2437 | AC36: =+SUM(BH36)-SUM(Z36:AB36) -> 2790 | AD36: 1814 | AE36: 1641 | AF36: 2134 | AG36: =+SUM(BI36)-SUM(AD36:AF36) -> 2714 | AH36: 1738 | AI36: 2197 | AJ36: =18954-15930 -> 3024 | AK36: 2586 | AL36: =+AL35*0.14 -> 3045.28 | AX36: 1254 | AY36: 1970 | AZ36: 2506 | BA36: 2301 | BB36: 4660 | BC36: 3249 | BD36: 6237 | BE36: 4034 | BF36: 7914 | BG36: 5619 | BH36: 8330 | BI36: 8303 | BJ36: 9545 | BK36: =+BK35*BK45 -> 12401.318 | BL36: =+BL35*BL45 -> 15497.043 | BM36: =+BM35*BM45 -> 19038.679 | BN36: =+BN35*BN45 -> 23411.664 | BO36: =+BO35*BO45 -> 28758.48 | BP36: =+BP35*BP45 -> 34635.502
B37: net inc | N37: =N35-N36 -> 4902 | O37: =O35-O36 -> 5178 | R37: =R35-R36 -> 9497 | S37: =S35-S36 -> 10394 | V37: =V35-V36 -> 7465 | W37: =W35-W36 -> 6687 | Z37: =Z35-Z36 -> 5709 | AA37: =AA35-AA36 -> 7788 | AB37: =AB35-AB36 -> 11583 | AC37: =+SUM(BH37)-SUM(Z37:AB37) -> 14018 | AD37: =AD35-AD36 -> 12369 | AE37: =AE35-AE36 -> 13465 | AF37: =AF35-AF36 -> 15688 | AG37: =+SUM(BI37)-SUM(AD37:AF37) -> 20838 | AH37: =AH35-AH36 -> 16644 | AI37: =AI35-AI36 -> 18337 | AJ37: =AJ35-AJ36 -> 18639 | AK37: =AK35-AK36 -> 22768 | AL37: =AL35-AL36 -> 18706.72 | AM37: 18270 | AN37: 18350 | AO37: 22270 | AX37: =AX35-AX36 -> 1500 | AY37: =AY35-AY36 -> 2940 | AZ37: =AZ35-AZ36 -> 3688 | BA37: =BA35-BA36 -> 10217 | BB37: =BB35-BB36 -> 15934 | BC37: =BC35-BC36 -> 22112 | BD37: =BD35-BD36 -> 18575 | BE37: =BE35-BE36 -> 29146 | ... BP37: =BP35-BP36 -> 231791.44 | BQ37: =+BQ26*BQ48 -> 215519.44 | BR37: =+BR26*BR48 -> 251267.86 | BS37: =+BS26*BS48 -> 292945.91 | BT37: =+BT26*BT48 -> 341537.15 | BU37: =BT37*(1+$BY$42) -> 344952.52 | BV37: =BU37*(1+$BY$42) -> 348402.04 | BW37: =BV37*(1+$BY$42) -> 351886.06 | BX37: =BW37*(1+$BY$42) -> 355404.92 | BY37: =BX37*(1+$BY$42) -> 358958.97 | BZ37: =BY37*(1+$BY$42) -> 362548.56 | CA37: =BZ37*(1+$BY$42) -> 366174.05 | CB37: =CA37*(1+$BY$42) -> 369835.79 | ... FP37: =FO37*(1+$BY$42) -> 923794.4
B38: eps | N38: 1.72 | O38: 1.82 | R38: 3.34 | S38: 3.67 | V38: 2.74 | W38: 2.47 | Z38: 2.21 | AA38: 3.03 | AB38: 4.5 | AC38: =+SUM(BH38)-SUM(Z38:AB38) -> 5.45 | AD38: 4.86 | AE38: 5.31 | AF38: 6.2 | AG38: =+SUM(BI38)-SUM(AD38:AF38) -> 8.24 | AH38: 6.59 | AI38: =+AI37/AI39 -> 7.282367 | AJ38: =+AJ37/AJ39 -> 7.4052443 | AK38: =+AK37/AK39 -> 9.0170297 | AL38: =+AL37/AL39 -> 7.3822889 | AM38: 7.14 | AN38: 7.15 | AO38: 8.66 | AX38: =+AX37/AX39 -> 0.61983471 | AY38: =+AY37/AY39 -> 1.1247131 | AZ38: =+AZ37/AZ39 -> 1.3157331 | BA38: 3.56 | BB38: 5.49 | BC38: 7.65 | BD38: 6.48 | BE38: 10.22 | BF38: 13.99 | BG38: 8.63 | BH38: 15.19 | BI38: 24.61 | BJ38: =+BJ37/BJ39 -> 30.300278
B39: s/o | N39: 2851 | O39: 2850 | R39: 2847 | S39: 2834 | V39: 2725 | W39: 2704 | Z39: 2587 | AA39: 2568 | AB39: 2576 | AC39: 2574 | AD39: 2545 | AE39: 2534 | AF39: 2529 | AG39: 2534 | AH39: 2527 | AI39: 2518 | AJ39: 2517 | AK39: 2525 | AL39: 2534 | AX39: 2420 | AY39: 2614 | AZ39: 2803 | BA39: 2863 | BB39: 2901 | BC39: 2890 | BD39: 2854 | BE39: 2851 | BF39: 2815 | BG39: 2687 | BH39: 2574 | BI39: 2534 | BJ39: 2521
B42: DAP | S42: =+S13/O13-1 -> 0.07182525 | T42: =+T13/P13-1 -> 0.062043796 | U42: =+U13/Q13-1 -> 0.040400429 | V42: =+V13/R13-1 -> 0.00595864 | W42: =+W13/S13-1 -> -0.0051813472 | X42: =+X13/T13-1 -> 0.0068728522 | Y42: =+Y13/U13-1 -> 0.017182131 | Z42: =+Z13/V13-1 -> 0.052264808 | ... AL42: =+AL13/AH13-1 -> 0.037900875 | BD42: =+BD13/BC13-1 -> 0.11330049 | BE42: =+BE13/BD13-1 -> 0.15044248 | BF42: =+BF13/BE13-1 -> 0.084615385 | BG42: =+BG13/BF13-1 -> 0.04964539 | BH42: =+BH13/BG13-1 -> 0.077702703 | BI42: =+BI13/BH13-1 -> 0.05015674 | BJ42: =+BJ13/BI13-1 -> 0.056716418 | BK42: 0.057 | BL42: 0.057 | BM42: 0.057 | BN42: 0.057 | BO42: 0.057 | BP42: 0.057 | BQ42: 0.057 | BR42: 0.057 | BS42: 0.057 | BT42: 0.057 | BX42: terminal | BY42: 0.01
B43: ARPP | S43: =+S14/O14-1 -> 0.45173059 | AC43: =+AC14/Y14-1 -> 0.15449438 | AD43: =+AD14/Z14-1 -> 0.18268215 | AE43: =+AE14/AA14-1 -> 0.14107486 | AF43: =+AF14/AB14-1 -> 0.12442818 | AG43: =+AG14/AC14-1 -> 0.15571776 | AH43: =+AH14/AD14-1 -> 0.10146814 | AI43: =+AI14/AE14-1 -> 0.1483619 | AJ43: =+AJ14/AF14-1 -> 0.17779831 | ... AL43: =+AL14/AH14-1 -> 0.28219264 | BE43: =+BE14/BD14-1 -> 0.15 | BF43: =+BF14/BE14-1 -> 0.15 | BG43: =+BG14/BF14-1 -> 0.15 | BH43: =+BH14/BG14-1 -> 0.15 | BI43: =+BI14/BH14-1 -> 0.15 | BJ43: =+BJ14/BI14-1 -> 0.10255894 | BK43: 0.103 | BL43: 0.103 | BM43: 0.103 | BN43: 0.103 | BO43: 0.103 | BP43: 0.103 | BQ43: 0.103 | BR43: 0.103 | BS43: 0.103 | BT43: 0.103 | BX43: discount | BY43: 0.07
B44: revenue | Q44: =Q26/M26-1 -> 0.33156247 | R44: =R26/N26-1 -> 0.47550319 | S44: =S26/O26-1 -> 0.5560015 | T44: =T26/P26-1 -> 0.3511877 | U44: =U26/Q26-1 -> 0.19945141 | V44: =V26/R26-1 -> 0.066371174 | W44: =W26/S26-1 -> -0.0087698181 | Z44: =Z26/V26-1 -> 0.026408198 | AA44: =AA26/W26-1 -> 0.1102283 | AC44: =AC26/Y26-1 -> 0.2470698 | AD44: =AD26/Z26-1 -> 0.27264793 | AE44: =AE26/AA26-1 -> 0.22100691 | AF44: =AF26/AB26-1 -> 0.18868974 | AG44: =AG26/AC26-1 -> 0.20627244 | AH44: =AH26/AD26-1 -> 0.16071869 | AI44: =AI26/AE26-1 -> 0.21614497 | AJ44: =AJ26/AF26-1 -> 0.26246027 | ... AO44: =AO26/AK26-1 -> 0.21616883 | AY44: =AY26/AX26-1 -> 0.5835874 | AZ44: =AZ26/AY26-1 -> 0.43815177 | BA44: =BA26/AZ26-1 -> 0.54161089 | BB44: =BB26/BA26-1 -> 0.47090962 | BC44: =BC26/BB26-1 -> 0.37352717 | BD44: =BD26/BC26-1 -> 0.2661091 | BE44: =BE26/BD26-1 -> 0.2159639 | BF44: =BF26/BE26-1 -> 0.37182574 | ... BT44: =BT26/BS26-1 -> 0.165871 | BX44: ROIC | BY44: 0.02
B45: tax rate | N45: =N36/N35 -> 0.16362395 | O45: =O36/O35 -> 0.15543957 | R45: =R36/R35 -> 0.17438929 | S45: =S36/S35 -> 0.16934388 | V45: =V36/V35 -> 0.16198922 | W45: =W36/W35 -> 0.18311752 | Z45: =Z36/Z35 -> 0.2186944 | AA45: =AA36/AA35 -> 0.16194985 | AB45: =AB36/AB35 -> 0.17382311 | AC45: =AC36/AC35 -> 0.16599238 | AD45: =AD36/AD35 -> 0.1278996 | AE45: =AE36/AE35 -> 0.10863233 | AF45: =AF36/AF35 -> 0.11973965 | AG45: =AG36/AG35 -> 0.11523438 | ... AK45: =AK36/AK35 -> 0.10199574 | AL45: -0.23082935 | AX45: =AX36/AX35 -> 0.45533769 | AY45: =AY36/AY35 -> 0.401222 | AZ45: =AZ36/AZ35 -> 0.40458508 | BA45: =BA36/BA35 -> 0.18381531 | BB45: =BB36/BB35 -> 0.2262795 | BC45: =BC36/BC35 -> 0.12811009 | BD45: =BD36/BD35 -> 0.2513703 | BE45: =BE36/BE35 -> 0.12157926 | ... BJ45: =BJ36/BJ35 -> 0.1110762 | BK45: 0.13 | BL45: 0.13 | BM45: 0.13 | BN45: 0.13 | BO45: 0.13 | BP45: 0.13 | BX45: NPV | BY45: =+NPV(BY43,BK37:FP37)+Main!J11-Main!J12 -> 4232705
B46: GM | N46: =(N26-N27)/N26 -> 0.80498393 | O46: =(O26-O27)/O26 -> 0.7950982 | R46: =(R26-R27)/R26 -> 0.8039433 | S46: =(S26-S27)/S26 -> 0.8143206 | V46: =(V26-V27)/V26 -> 0.78482872 | W46: =(W26-W27)/W26 -> 0.81985983 | Z46: =(Z26-Z27)/Z26 -> 0.78676907 | AA46: =(AA26-AA27)/AA26 -> 0.81421294 | AB46: =(AB26-AB27)/AB26 -> 0.8181339 | AC46: =(AC26-AC27)/AC26 -> 0.80813722 | AD46: =(AD26-AD27)/AD26 -> 0.81785763 | AE46: =(AE26-AE27)/AE26 -> 0.8129559 | AF46: =(AF26-AF27)/AF26 -> 0.81830052 | AG46: =(AG26-AG27)/AG26 -> 0.81734386 | ... AL46: =(AL26-AL27)/AL26 -> 0.81854345 | AX46: =(AX26-AX27)/AX26 -> 0.76181402 | AY46: =(AY26-AY27)/AY26 -> 0.82729023 | AZ46: =(AZ26-AZ27)/AZ26 -> 0.84008255 | BA46: =(BA26-BA27)/BA26 -> 0.86290614 | BB46: =(BB26-BB27)/BB26 -> 0.86584016 | BC46: =(BC26-BC27)/BC26 -> 0.83246176 | BD46: =(BD26-BD27)/BD26 -> 0.81936999 | BE46: =(BE26-BE27)/BE26 -> 0.80582795 | ... BK46: =(BK26-BK27)/BK26 -> 0.81107074 | BL46: 0.82 | BM46: 0.82 | BN46: 0.82 | BO46: 0.82 | BP46: 0.82 | BX46: PS | BY46: =+BY45/Main!J9 -> 1667.4544
B47: OM | N47: =+N33/N26 -> 0.33224333 | O47: =+O33/O26 -> 0.31909884 | R47: =+R33/R26 -> 0.43475603 | S47: =+S33/S26 -> 0.42531898 | V47: =+V33/V26 -> 0.30543213 | W47: =+W33/W26 -> 0.28998682 | Z47: =+Z33/Z26 -> 0.25229534 | AA47: =+AA33/AA26 -> 0.29350917 | AB47: =+AB33/AB26 -> 0.40262403 | AC47: =+AC33/AC26 -> 0.40845632 | AD47: =+AD33/AD26 -> 0.37904266 | AE47: =+AE33/AE26 -> 0.38000051 | AF47: =+AF33/AF26 -> 0.42745571 | AG47: =+AG33/AG26 -> 0.48288761 | ... AL47: =+AL33/AL26 -> 0.40617286 | AX47: =+AX33/AX26 -> 0.35619919 | AY47: =+AY33/AY26 -> 0.40060966 | AZ47: =+AZ33/AZ26 -> 0.34722222 | BA47: =+BA33/BA26 -> 0.44963456 | BB47: =+BB33/BB26 -> 0.49696209 | BC47: =+BC33/BC26 -> 0.44616569 | BD47: =+BD33/BD26 -> 0.33927889 | BE47: =+BE33/BE26 -> 0.38005002 | ... BP47: =+BP33/BP26 -> 0.5170558 | BX47: up | BY47: =+BY46/Main!J8-1 -> 1.8898689
B48: PM | N48: =N37/N26 -> 0.27637143 | O48: =O37/O26 -> 0.27709103 | R48: =R37/R26 -> 0.36288258 | S48: =S37/S26 -> 0.35746466 | V48: =V37/V26 -> 0.26748603 | W48: =W37/W26 -> 0.23201027 | Z48: =Z37/Z26 -> 0.1993018 | AA48: =AA37/AA26 -> 0.24338261 | AB48: =AB37/AB26 -> 0.33921982 | AC48: =AC37/AC26 -> 0.34947148 | AD48: =AD37/AD26 -> 0.33929502 | AE48: =AE37/AE26 -> 0.34462901 | AF48: =AF37/AF26 -> 0.38650866 | AG48: =AG37/AG26 -> 0.43066176 | ... AO48: =AO37/AO26 -> 0.30573861 | AX48: =AX37/AX26 -> 0.19054878 | AY48: =AY37/AY26 -> 0.23584149 | AZ48: =AZ37/AZ26 -> 0.20571174 | BA48: =BA37/BA26 -> 0.36967219 | BB48: =BB37/BB26 -> 0.39195139 | BC48: =BC37/BC26 -> 0.39600272 | BD48: =BD37/BD26 -> 0.26274099 | BE48: =BE37/BE26 -> 0.33904496 | ... BP48: =BP37/BP26 -> 0.4764804 | BQ48: 0.38 | BR48: 0.38 | BS48: 0.38 | BT48: 0.38
B51: CFO | Z51: =+SUM(Z54:Z60) -> 11427 | AA51: =+SUM(AA54:AA60) -> 13777 | AB51: =+SUM(AB54:AB60) -> 21397 | AC51: =+SUM(AC54:AC60) -> 20676 | AD51: =+SUM(AD54:AD60) -> 19023 | AE51: =+SUM(AE54:AE60) -> 20111 | AF51: =+SUM(AF54:AF60) -> 22654 | AG51: =+SUM(AG54:AG60) -> 28492 | ... AL51: =+SUM(AL54:AL60) -> 39985 | AX51: =+SUM(AX54:AX60) -> 3546 | AY51: =+SUM(AY54:AY60) -> 5719 | AZ51: =+SUM(AZ54:AZ60) -> 9536 | BA51: =+SUM(BA54:BA60) -> 15350 | BB51: =+SUM(BB54:BB60) -> 22329 | BC51: =+SUM(BC54:BC60) -> 30801 | BD51: =+SUM(BD54:BD60) -> 29154 | BE51: =+SUM(BE54:BE60) -> 41470 | ... BJ51: =+SUM(BJ54:BJ60) -> 116685
B54: Net income | N54: =N37 -> 4902 | O54: =O37 -> 5178 | R54: =R37 -> 9497 | S54: =S37 -> 10394 | V54: =V37 -> 7465 | W54: =W37 -> 6687 | Z54: =Z37 -> 5709 | AA54: =AA37 -> 7788 | AB54: =AB37 -> 11583 | AC54: =AC37 -> 14018 | AD54: =AD37 -> 12369 | AE54: =AE37 -> 13465 | AF54: =AF37 -> 15688 | AG54: =AG37 -> 20838 | ... AI54: =AI37 -> 18337 | AJ54: 2709 | AK54: =AK37 -> 22768 | AL54: 26773 | AX54: =AX37 -> 1500 | AY54: =AY37 -> 2940 | AZ54: =AZ37 -> 3688 | BA54: =BA37 -> 10217 | BB54: =BB37 -> 15934 | BC54: =BC37 -> 22112 | BD54: =BD37 -> 18575 | BE54: =BE37 -> 29146 | ... BI54: =BI37 -> 62360 | BJ54: 60458
B55: D&A | N55: 1597 | O55: 1704 | R55: 1972 | S55: 1986 | V55: 2156 | W55: 1979 | Z55: 2524 | AA55: 2623 | AB55: 2859 | AC55: =+SUM(BH55)-SUM(Z55:AB55) -> 3172 | AD55: 3374 | AE55: 3637 | AF55: 4027 | AG55: =+SUM(BI55)-SUM(AD55:AF55) -> 4460 | AH55: 3900 | AI55: 4342 | AJ55: 4963 | AK55: 5411 | AL55: 5999 | AX55: 1011 | AY55: 1243 | AZ55: 1945 | BA55: 2342 | BB55: 3025 | BC55: 4315 | BD55: 5741 | BE55: 6862 | BF55: 7967 | BG55: 8686 | BH55: 11178 | BI55: 15498 | BJ55: 18616
B56: share comp | N56: 1335 | O56: 1695 | R56: 1830 | S56: 2549 | V56: 2498 | W56: 3352 | Z56: 3051 | AA56: 4060 | AB56: 3492 | AC56: =+SUM(BH56)-SUM(Z56:AB56) -> 3424 | AD56: 3562 | AE56: 4616 | AF56: 4250 | AG56: =+SUM(BI56)-SUM(AD56:AF56) -> 4262 | AH56: 4147 | AI56: 4834 | AJ56: 5556 | AK56: 5890 | AL56: 6032 | AX56: 906 | AY56: 1786 | AZ56: 2960 | BA56: 3218 | BB56: 3723 | BC56: 4152 | BD56: 4836 | BE56: 6536 | BF56: 9164 | BG56: 11992 | BH56: 14027 | BI56: 16690 | BJ56: 20427
...
